<?xml version="1.0" ?>
<sdf version="1.8">
    <model name='diff_drive'>

      <plugin filename="gz-sim-imu-system"
        name="gz::sim::systems::Imu">
      </plugin>

      <plugin 
        filename="libignition-gazebo-imu-system.so"
        name="ignition::gazebo::systems::Imu">
      </plugin>

      <plugin
        filename="gz-sim-sensors-system"
        name="gz::sim::systems::Sensors">
        <render_engine>ogre2</render_engine>
      </plugin>

      <plugin
        filename="gz-sim-joint-state-publisher-system"
        name="gz::sim::systems::JointStatePublisher">
      </plugin>

      <plugin
        filename="gz-sim-pose-publisher-system"
        name="gz::sim::systems::PosePublisher">
        <publish_link_pose>true</publish_link_pose>
        <use_pose_vector_msg>true</use_pose_vector_msg>
        <static_publisher>true</static_publisher>
        <static_update_frequency>1</static_update_frequency>
      </plugin>

      <plugin
        filename="gz-sim-odometry-publisher-system"
        name="gz::sim::systems::OdometryPublisher">
        <odom_frame>diff_drive/odom</odom_frame>
        <robot_base_frame>diff_drive</robot_base_frame>
      </plugin>

      <plugin
        filename="ignition-gazebo-diff-drive-system"
        name="ignition::gazebo::systems::DiffDrive">
        <left_joint>left_wheel_joint</left_joint>
        <right_joint>right_wheel_joint</right_joint>
        <wheel_separation>1.25</wheel_separation>
        <wheel_radius>0.3</wheel_radius>
        <odom_publish_frequency>1</odom_publish_frequency>
        <max_linear_acceleration>2</max_linear_acceleration>
        <min_linear_acceleration>-2</min_linear_acceleration>
        <max_angular_acceleration>2</max_angular_acceleration>
        <min_angular_acceleration>-2</min_angular_acceleration>
        <max_linear_velocity>0.5</max_linear_velocity>
        <min_linear_velocity>-0.5</min_linear_velocity>
        <max_angular_velocity>1</max_angular_velocity>
        <min_angular_velocity>-1</min_angular_velocity>
      </plugin>

      <link name='chassis'>
        <pose>-0.151427 -0 0.175 0 -0 0</pose>
        <inertial>
          <mass>1.14395</mass>
          <inertia>
            <ixx>0.126164</ixx>
            <ixy>0</ixy>
            <ixz>0</ixz>
            <iyy>0.416519</iyy>
            <iyz>0</iyz>
            <izz>0.481014</izz>
          </inertia>
        </inertial>
        <visual name='visual_chassis'>
          <geometry>
            <box>
              <size>2.01142 1 0.568726</size>
            </box>
          </geometry>
          <material>
            <ambient>0.5 0.5 1.0 1</ambient>
            <diffuse>0.5 0.5 1.0 1</diffuse>
            <specular>0.0 0.0 1.0 1</specular>
          </material>
        </visual>
        <collision name='collision_chassis'>
          <geometry>
            <box>
              <size>2.01142 1 0.568726</size>
            </box>
          </geometry>
        </collision>
        <!-- <sensor name='imu_sensor' type='imu'>
          <ignition_frame_id>diff_drive/imu_link</ignition_frame_id>
          <always_on>1</always_on>
          <update_rate>1000</update_rate>
          <visualize>1</visualize>
          <topic>imu</topic>
          <pose>0 0 0 0 0 0</pose>
        </sensor> -->

        <sensor name='gpu_lidar1' type='gpu_lidar'>"
          <topic>/diff_drive/lidar</topic>
          <update_rate>10</update_rate>
          <ignition_frame_id>diff_drive/chassis</ignition_frame_id>
          <ray>
            <scan>
                <horizontal>
                    <samples>640</samples>
                    <resolution>1</resolution>
                    <min_angle>-1.396263</min_angle>
                    <max_angle>1.396263</max_angle>
                </horizontal>
                <vertical>
                    <samples>1</samples>
                    <resolution>0.01</resolution>
                    <min_angle>0</min_angle>
                    <max_angle>0</max_angle>
                </vertical>
            </scan>
            <range>
                <min>0.08</min>
                <max>10.0</max>
                <resolution>0.01</resolution>
            </range>
          </ray>
          <always_on>1</always_on>
          <visualize>true</visualize>
        </sensor>

        <!-- <sensor name="depth" type="depth_camera">
          <ignition_frame_id>diff_drive/imu_link</ignition_frame_id>
          <update_rate>6</update_rate>
          <always_on>0</always_on>
          <camera>
            <horizontal_fov>1.51843645</horizontal_fov>
            <image>
              <width>848</width>
              <height>480</height>
              <format>R_FLOAT32</format>
            </image>
            <clip>
              <near>0.1</near>
              <far>10</far>
            </clip>
            <lens>
              <intrinsics>
                <fx>421.61578369140625</fx>
                <fy>421.61578369140625</fy>
                <cx>422.2854309082031</cx>
                <cy>236.57237243652344</cy>
                <s>0</s>
              </intrinsics>
            </lens>
          </camera>
        </sensor> -->
      </link>

      <link name='tank_tower'>
        <pose>0.151427 -0 0.568726 -1.5707 0 0</pose>
        <inertial>
          <mass>2</mass>
          <inertia>
            <ixx>0.145833</ixx>
            <ixy>0</ixy>
            <ixz>0</ixz>
            <iyy>0.145833</iyy>
            <iyz>0</iyz>
            <izz>0.125</izz>
          </inertia>
        </inertial>
        <visual name='visual_left_wheel'>
          <geometry>
            <sphere>
              <radius>0.3</radius>
            </sphere>
          </geometry>
          <material>
            <ambient>0.2 0.2 0.2 1</ambient>
            <diffuse>0.2 0.2 0.2 1</diffuse>
            <specular>0.2 0.2 0.2 1</specular>
          </material>
        </visual>
        <collision name='collision_left_wheel'>
          <geometry>
            <sphere>
              <radius>0.3</radius>
            </sphere>
          </geometry>
        </collision>
      </link>

      <link name='left_wheel'>
        <pose>0.554283 0.625029 -0.025 -1.5707 0 0</pose>
        <inertial>
          <mass>2</mass>
          <inertia>
            <ixx>0.145833</ixx>
            <ixy>0</ixy>
            <ixz>0</ixz>
            <iyy>0.145833</iyy>
            <iyz>0</iyz>
            <izz>0.125</izz>
          </inertia>
        </inertial>
        <visual name='visual_left_wheel'>
          <geometry>
            <sphere>
              <radius>0.3</radius>
            </sphere>
          </geometry>
          <material>
            <ambient>0.2 0.2 0.2 1</ambient>
            <diffuse>0.2 0.2 0.2 1</diffuse>
            <specular>0.2 0.2 0.2 1</specular>
          </material>
        </visual>
        <collision name='collision_left_wheel'>
          <geometry>
            <sphere>
              <radius>0.3</radius>
            </sphere>
          </geometry>
        </collision>
      </link>

      <link name='right_wheel'>
        <pose>0.554282 -0.625029 -0.025 -1.5707 0 0</pose>
        <inertial>
          <mass>2</mass>
          <inertia>
            <ixx>0.145833</ixx>
            <ixy>0</ixy>
            <ixz>0</ixz>
            <iyy>0.145833</iyy>
            <iyz>0</iyz>
            <izz>0.125</izz>
          </inertia>
        </inertial>
        <visual name='visual_right_wheel'>
          <geometry>
            <sphere>
              <radius>0.3</radius>
            </sphere>
          </geometry>
          <material>
            <ambient>0.2 0.2 0.2 1</ambient>
            <diffuse>0.2 0.2 0.2 1</diffuse>
            <specular>0.2 0.2 0.2 1</specular>
          </material>
        </visual>
        <collision name='collision_right_wheel'>
          <geometry>
            <sphere>
              <radius>0.3</radius>
            </sphere>
          </geometry>
        </collision>
      </link>

      <link name='left_caster'>
        <pose>-0.957138 0.625029 -0.025 0 -0 0</pose>
        <inertial>
          <mass>2</mass>
          <inertia>
            <ixx>0.145833</ixx>
            <ixy>0</ixy>
            <ixz>0</ixz>
            <iyy>0.145833</iyy>
            <iyz>0</iyz>
            <izz>0.125</izz>
          </inertia>
        </inertial>
        <visual name='visual_caster'>
          <geometry>
            <sphere>
              <radius>0.3</radius>
            </sphere>
          </geometry>
          <material>
            <ambient>0.2 0.2 0.2 1</ambient>
            <diffuse>0.2 0.2 0.2 1</diffuse>
            <specular>0.2 0.2 0.2 1</specular>
          </material>
        </visual>
        <collision name='collision_caster'>
          <geometry>
            <sphere>
              <radius>0.3</radius>
            </sphere>
          </geometry>
        </collision>
      </link>

      <link name='right_caster'>
        <pose>-0.957138 -0.625029 -0.025 0 -0 0</pose>
        <inertial>
          <mass>2</mass>
          <inertia>
            <ixx>0.145833</ixx>
            <ixy>0</ixy>
            <ixz>0</ixz>
            <iyy>0.145833</iyy>
            <iyz>0</iyz>
            <izz>0.125</izz>
          </inertia>
        </inertial>
        <visual name='visual_caster'>
          <geometry>
            <sphere>
              <radius>0.3</radius>
            </sphere>
          </geometry>
          <material>
            <ambient>0.2 0.2 0.2 1</ambient>
            <diffuse>0.2 0.2 0.2 1</diffuse>
            <specular>0.2 0.2 0.2 1</specular>
          </material>
        </visual>
        <collision name='collision_caster'>
          <geometry>
            <sphere>
              <radius>0.3</radius>
            </sphere>
          </geometry>
        </collision>
      </link>

      <joint name='left_wheel_joint' type='revolute'>
        <parent>chassis</parent>
        <child>left_wheel</child>
        <axis>
          <xyz>0 0 1</xyz>
          <limit>
            <lower>-1.79769e+308</lower>
            <upper>1.79769e+308</upper>
          </limit>
        </axis>
      </joint>

      <joint name='right_wheel_joint' type='revolute'>
        <parent>chassis</parent>
        <child>right_wheel</child>
        <axis>
          <xyz>0 0 1</xyz>
          <limit>
            <lower>-1.79769e+308</lower>
            <upper>1.79769e+308</upper>
          </limit>
        </axis>
      </joint>

      <joint name='tank_tower_joint' type='revolute'>
        <parent>chassis</parent>
        <child>tank_tower</child>
        <axis>
          <xyz>0 0 1</xyz>
          <limit>
            <lower>-1.79769e+308</lower>
            <upper>1.79769e+308</upper>
          </limit>
        </axis>
      </joint>

      <joint name='left_caster_joint' type='ball'>
        <parent>chassis</parent>
        <child>left_caster</child>
      </joint>

      <joint name='right_caster_joint' type='ball'>
        <parent>chassis</parent>
        <child>right_caster</child>
      </joint>

    </model>
</sdf>
